<?xml version="1.0" ?>
<robot name="robot" xmlns:xacro="http://www.ros.org/wiki/xacro">

<xacro:include filename="$(find robot_description)/urdf/materials.xacro" />
<xacro:include filename="$(find robot_description)/urdf/robot.trans" />
<xacro:include filename="$(find robot_description)/urdf/robot.gazebo" />

<link name="base_link">
  <inertial>
    <origin xyz="-0.3497034480857745 -0.4961224133505976 0.09428441033844955" rpy="0 0 0"/>
    <mass value="17.719416949374274"/>
    <inertia ixx="0.704305" iyy="1.471877" izz="1.004356" ixy="-0.000419" iyz="-0.000142" ixz="-0.000745"/>
  </inertial>
  <visual>
    <origin xyz="0 0 0" rpy="1.5708 0 0"/>
    <geometry>
      <mesh filename="package://robot_description/meshes/base_link.stl" scale="0.001 0.001 0.001"/>
    </geometry>
    <material name="silver"/>
  </visual>
  <collision>
    <origin xyz="0 0 0" rpy="1.5708 0 0"/>
    <geometry>
      <mesh filename="package://robot_description/meshes/base_link.stl" scale="0.001 0.001 0.001"/>
    </geometry>
  </collision>
</link>

<link name="right_big_pivot_1">
  <inertial>
    <origin xyz="-0.05850375195341356 -0.10854805486368158 -0.07469415008418884" rpy="0 0 0"/>
    <mass value="2.2415377387384887"/>
    <inertia ixx="0.033507" iyy="0.086535" izz="0.078447" ixy="-0.014743" iyz="-1e-06" ixz="2e-05"/>
  </inertial>
  <visual>
    <origin xyz="0.34925 0.734527 -0.14605" rpy="1.5708 0 0"/>
    <geometry>
      <mesh filename="package://robot_description/meshes/right_big_pivot_1.stl" scale="0.001 0.001 0.001"/>
    </geometry>
    <material name="silver"/>
  </visual>
  <collision>
    <origin xyz="0.34925 0.734527 -0.14605" rpy="1.5708 0 0"/>
    <geometry>
      <mesh filename="package://robot_description/meshes/right_big_pivot_1.stl" scale="0.001 0.001 0.001"/>
    </geometry>
  </collision>
</link>

<link name="left_big_pivot_1">
  <inertial>
    <origin xyz="-0.05850375195478724 0.1086219451363166 -0.07469415008419117" rpy="0 0 0"/>
    <mass value="2.2415377387384736"/>
    <inertia ixx="0.033507" iyy="0.086535" izz="0.078447" ixy="-0.014743" iyz="-1e-06" ixz="2e-05"/>
  </inertial>
  <visual>
    <origin xyz="0.34925 0.257568 -0.14605" rpy="1.5708 0 0"/>
    <geometry>
      <mesh filename="package://robot_description/meshes/left_big_pivot_1.stl" scale="0.001 0.001 0.001"/>
    </geometry>
    <material name="silver"/>
  </visual>
  <collision>
    <origin xyz="0.34925 0.257568 -0.14605" rpy="1.5708 0 0"/>
    <geometry>
      <mesh filename="package://robot_description/meshes/left_big_pivot_1.stl" scale="0.001 0.001 0.001"/>
    </geometry>
  </collision>
</link>

<link name="right_little_pivot_1">
  <inertial>
    <origin xyz="-0.00022059559125406358 -0.10783319760475599 -0.03446395454671583" rpy="0 0 0"/>
    <mass value="1.158287566383538"/>
    <inertia ixx="0.010707" iyy="0.023908" izz="0.01462" ixy="8.5e-05" iyz="0.000121" ixz="1e-06"/>
  </inertial>
  <visual>
    <origin xyz="0.174498 0.043573 0.0127" rpy="1.5708 0 0"/>
    <geometry>
      <mesh filename="package://robot_description/meshes/right_little_pivot_1.stl" scale="0.001 0.001 0.001"/>
    </geometry>
    <material name="silver"/>
  </visual>
  <collision>
    <origin xyz="0.174498 0.043573 0.0127" rpy="1.5708 0 0"/>
    <geometry>
      <mesh filename="package://robot_description/meshes/right_little_pivot_1.stl" scale="0.001 0.001 0.001"/>
    </geometry>
  </collision>
</link>

<link name="left_little_pivot_1">
  <inertial>
    <origin xyz="-0.00022059558986731176 0.10298680239524349 -0.03446395454671311" rpy="0 0 0"/>
    <mass value="1.158287566383538"/>
    <inertia ixx="0.010707" iyy="0.023908" izz="0.01462" ixy="8.5e-05" iyz="0.000121" ixz="1e-06"/>
  </inertial>
  <visual>
    <origin xyz="0.174498 0.948649 0.0127" rpy="1.5708 0 0"/>
    <geometry>
      <mesh filename="package://robot_description/meshes/left_little_pivot_1.stl" scale="0.001 0.001 0.001"/>
    </geometry>
    <material name="silver"/>
  </visual>
  <collision>
    <origin xyz="0.174498 0.948649 0.0127" rpy="1.5708 0 0"/>
    <geometry>
      <mesh filename="package://robot_description/meshes/left_little_pivot_1.stl" scale="0.001 0.001 0.001"/>
    </geometry>
  </collision>
</link>

<link name="wheel_1">
  <inertial>
    <origin xyz="8.376931592835035e-09 0.08910710362063429 -4.49129045065888e-09" rpy="0 0 0"/>
    <mass value="11.601933377005569"/>
    <inertia ixx="0.066678" iyy="0.066678" izz="0.074767" ixy="0.0" iyz="-0.0" ixz="0.0"/>
  </inertial>
  <visual>
    <origin xyz="0.698754 0.254393 0.10795" rpy="1.5708 0 0"/>
    <geometry>
      <mesh filename="package://robot_description/meshes/wheel_1.stl" scale="0.001 0.001 0.001"/>
    </geometry>
    <material name="silver"/>
  </visual>
  <collision>
    <origin xyz="0.698754 0.254393 0.10795" rpy="1.5708 0 0"/>
    <geometry>
      <mesh filename="package://robot_description/meshes/wheel_1.stl" scale="0.001 0.001 0.001"/>
    </geometry>
  </collision>
</link>

<link name="wheel_2">
  <inertial>
    <origin xyz="-7.764208220795155e-08 -0.08910782454769867 -4.0233125182809193e-07" rpy="0 0 0"/>
    <mass value="11.601933377005569"/>
    <inertia ixx="0.066678" iyy="0.066678" izz="0.074767" ixy="-0.0" iyz="-0.0" ixz="-0.0"/>
  </inertial>
  <visual>
    <origin xyz="0.352782 0.043573 0.08776" rpy="1.5708 0 0"/>
    <geometry>
      <mesh filename="package://robot_description/meshes/wheel_2.stl" scale="0.001 0.001 0.001"/>
    </geometry>
    <material name="silver"/>
  </visual>
  <collision>
    <origin xyz="0.352782 0.043573 0.08776" rpy="1.5708 0 0"/>
    <geometry>
      <mesh filename="package://robot_description/meshes/wheel_2.stl" scale="0.001 0.001 0.001"/>
    </geometry>
  </collision>
</link>

<link name="wheel_3">
  <inertial>
    <origin xyz="-3.618419096582462e-07 -0.089107824547699 -4.6688623511759175e-07" rpy="0 0 0"/>
    <mass value="11.601933377005569"/>
    <inertia ixx="0.066678" iyy="0.066678" izz="0.074767" ixy="-0.0" iyz="-0.0" ixz="-0.0"/>
  </inertial>
  <visual>
    <origin xyz="-0.002811 0.043573 0.090036" rpy="1.5708 0 0"/>
    <geometry>
      <mesh filename="package://robot_description/meshes/wheel_3.stl" scale="0.001 0.001 0.001"/>
    </geometry>
    <material name="silver"/>
  </visual>
  <collision>
    <origin xyz="-0.002811 0.043573 0.090036" rpy="1.5708 0 0"/>
    <geometry>
      <mesh filename="package://robot_description/meshes/wheel_3.stl" scale="0.001 0.001 0.001"/>
    </geometry>
  </collision>
</link>

<link name="wheel_4">
  <inertial>
    <origin xyz="8.378312821299971e-09 -0.08910782454769894 4.491294891550979e-09" rpy="0 0 0"/>
    <mass value="11.601933377005569"/>
    <inertia ixx="0.066678" iyy="0.066678" izz="0.074767" ixy="-0.0" iyz="-0.0" ixz="-0.0"/>
  </inertial>
  <visual>
    <origin xyz="0.698754 0.737702 0.10795" rpy="1.5708 0 0"/>
    <geometry>
      <mesh filename="package://robot_description/meshes/wheel_4.stl" scale="0.001 0.001 0.001"/>
    </geometry>
    <material name="silver"/>
  </visual>
  <collision>
    <origin xyz="0.698754 0.737702 0.10795" rpy="1.5708 0 0"/>
    <geometry>
      <mesh filename="package://robot_description/meshes/wheel_4.stl" scale="0.001 0.001 0.001"/>
    </geometry>
  </collision>
</link>

<link name="wheel_5">
  <inertial>
    <origin xyz="-7.764069687166142e-08 -0.08910782454769917 -4.0233124987132385e-07" rpy="0 0 0"/>
    <mass value="11.601933377005569"/>
    <inertia ixx="0.066678" iyy="0.066678" izz="0.074767" ixy="-0.0" iyz="-0.0" ixz="-0.0"/>
  </inertial>
  <visual>
    <origin xyz="0.352782 0.737829 0.08776" rpy="1.5708 0 0"/>
    <geometry>
      <mesh filename="package://robot_description/meshes/wheel_5.stl" scale="0.001 0.001 0.001"/>
    </geometry>
    <material name="silver"/>
  </visual>
  <collision>
    <origin xyz="0.352782 0.737829 0.08776" rpy="1.5708 0 0"/>
    <geometry>
      <mesh filename="package://robot_description/meshes/wheel_5.stl" scale="0.001 0.001 0.001"/>
    </geometry>
  </collision>
</link>

<link name="wheel_6">
  <inertial>
    <origin xyz="-3.618405238158505e-07 -0.08910782454769894 -4.6688623286939013e-07" rpy="0 0 0"/>
    <mass value="11.601933377005569"/>
    <inertia ixx="0.066678" iyy="0.066678" izz="0.074767" ixy="-0.0" iyz="-0.0" ixz="-0.0"/>
  </inertial>
  <visual>
    <origin xyz="-0.002811 0.737829 0.090036" rpy="1.5708 0 0"/>
    <geometry>
      <mesh filename="package://robot_description/meshes/wheel_6.stl" scale="0.001 0.001 0.001"/>
    </geometry>
    <material name="silver"/>
  </visual>
  <collision>
    <origin xyz="-0.002811 0.737829 0.090036" rpy="1.5708 0 0"/>
    <geometry>
      <mesh filename="package://robot_description/meshes/wheel_6.stl" scale="0.001 0.001 0.001"/>
    </geometry>
  </collision>
</link>

<joint name="Revolute 1" type="continuous">
  <origin xyz="-0.34925 -0.734527 0.14605" rpy="0 0 0"/>
  <parent link="base_link"/>
  <child link="right_big_pivot_1"/>
  <axis xyz="0.0 -1.0 0.0"/>
</joint>

<joint name="Revolute 3" type="continuous">
  <origin xyz="-0.34925 -0.257568 0.14605" rpy="0 0 0"/>
  <parent link="base_link"/>
  <child link="left_big_pivot_1"/>
  <axis xyz="0.0 1.0 0.0"/>
</joint>

<joint name="Revolute 4" type="continuous">
  <origin xyz="0.174752 0.213995 -0.15875" rpy="0 0 0"/>
  <parent link="left_big_pivot_1"/>
  <child link="right_little_pivot_1"/>
  <axis xyz="0.0 1.0 0.0"/>
</joint>

<joint name="Revolute 5" type="continuous">
  <origin xyz="0.174752 -0.214122 -0.15875" rpy="0 0 0"/>
  <parent link="right_big_pivot_1"/>
  <child link="left_little_pivot_1"/>
  <axis xyz="0.0 1.0 0.0"/>
</joint>

<joint name="Revolute 6" type="continuous">
  <origin xyz="-0.349504 0.003175 -0.254" rpy="0 0 0"/>
  <parent link="left_big_pivot_1"/>
  <child link="wheel_1"/>
  <axis xyz="0.0 -1.0 0.0"/>
</joint>

<joint name="Revolute 7" type="continuous">
  <origin xyz="-0.178284 0.0 -0.07506" rpy="0 0 0"/>
  <parent link="right_little_pivot_1"/>
  <child link="wheel_2"/>
  <axis xyz="0.0 -1.0 0.0"/>
</joint>

<joint name="Revolute 8" type="continuous">
  <origin xyz="0.177309 0.0 -0.077336" rpy="0 0 0"/>
  <parent link="right_little_pivot_1"/>
  <child link="wheel_3"/>
  <axis xyz="0.0 1.0 0.0"/>
</joint>

<joint name="Revolute 9" type="continuous">
  <origin xyz="-0.349504 -0.003175 -0.254" rpy="0 0 0"/>
  <parent link="right_big_pivot_1"/>
  <child link="wheel_4"/>
  <axis xyz="0.0 -1.0 0.0"/>
</joint>

<joint name="Revolute 10" type="continuous">
  <origin xyz="-0.178284 0.21082 -0.07506" rpy="0 0 0"/>
  <parent link="left_little_pivot_1"/>
  <child link="wheel_5"/>
  <axis xyz="0.0 -1.0 0.0"/>
</joint>

<joint name="Revolute 11" type="continuous">
  <origin xyz="0.177309 0.21082 -0.077336" rpy="0 0 0"/>
  <parent link="left_little_pivot_1"/>
  <child link="wheel_6"/>
  <axis xyz="0.0 1.0 0.0"/>
</joint>

</robot>