<?xml version="1.0" ?>
<robot name="robot" xmlns:xacro="http://www.ros.org/wiki/xacro">

<xacro:include filename="$(find robot_description)/urdf/materials.xacro" />
<xacro:include filename="$(find robot_description)/urdf/robot.trans" />
<xacro:include filename="$(find robot_description)/urdf/robot.gazebo" />
<link name="base_link">
  <inertial>
    <origin xyz="0.03180031010101302 4.6312625487061606e-05 0.27555741033921555" rpy="0 0 0"/>
    <mass value="17.719416949374274"/>
    <inertia ixx="0.704305" iyy="1.004356" izz="1.471877" ixy="0.000745" iyz="0.000142" ixz="-0.000419"/>
  </inertial>
  <visual>
    <origin xyz="0 0 0" rpy="0 0 0"/>
    <geometry>
      <mesh filename="package://robot_description/meshes/base_link.stl" scale="0.001 0.001 0.001"/>
    </geometry>
    <material name="silver"/>
  </visual>
  <collision>
    <origin xyz="0 0 0" rpy="0 0 0"/>
    <geometry>
      <mesh filename="package://robot_description/meshes/base_link.stl" scale="0.001 0.001 0.001"/>
    </geometry>
  </collision>
</link>

<link name="right_big_pivot_1">
  <inertial>
    <origin xyz="-0.05850399376662565 -0.10854732888759794 -0.07469415008342872" rpy="0 0 0"/>
    <mass value="2.2415377387384887"/>
    <inertia ixx="0.033507" iyy="0.078447" izz="0.086535" ixy="-2e-05" iyz="1e-06" ixz="-0.014743"/>
  </inertial>
  <visual>
    <origin xyz="-0.032254 0.238359 -0.327323" rpy="0 0 0"/>
    <geometry>
      <mesh filename="package://robot_description/meshes/right_big_pivot_1.stl" scale="0.001 0.001 0.001"/>
    </geometry>
    <material name="silver"/>
  </visual>
  <collision>
    <origin xyz="-0.032254 0.238359 -0.327323" rpy="0 0 0"/>
    <geometry>
      <mesh filename="package://robot_description/meshes/right_big_pivot_1.stl" scale="0.001 0.001 0.001"/>
    </geometry>
  </collision>
</link>

<link name="left_big_pivot_1">
  <inertial>
    <origin xyz="-0.05850399376799906 0.10862267111240001 -0.07469415008342606" rpy="0 0 0"/>
    <mass value="2.2415377387384736"/>
    <inertia ixx="0.033507" iyy="0.078447" izz="0.086535" ixy="-2e-05" iyz="1e-06" ixz="-0.014743"/>
  </inertial>
  <visual>
    <origin xyz="-0.032254 -0.2386 -0.327323" rpy="0 0 0"/>
    <geometry>
      <mesh filename="package://robot_description/meshes/left_big_pivot_1.stl" scale="0.001 0.001 0.001"/>
    </geometry>
    <material name="silver"/>
  </visual>
  <collision>
    <origin xyz="-0.032254 -0.2386 -0.327323" rpy="0 0 0"/>
    <geometry>
      <mesh filename="package://robot_description/meshes/left_big_pivot_1.stl" scale="0.001 0.001 0.001"/>
    </geometry>
  </collision>
</link>

<link name="right_little_pivot_1">
  <inertial>
    <origin xyz="-0.00022083740446587896 -0.10783247162867271 -0.03446395454594753" rpy="0 0 0"/>
    <mass value="1.158287566383538"/>
    <inertia ixx="0.010707" iyy="0.01462" izz="0.023908" ixy="-1e-06" iyz="-0.000121" ixz="8.5e-05"/>
  </inertial>
  <visual>
    <origin xyz="-0.207006 -0.452595 -0.168573" rpy="0 0 0"/>
    <geometry>
      <mesh filename="package://robot_description/meshes/right_little_pivot_1.stl" scale="0.001 0.001 0.001"/>
    </geometry>
    <material name="silver"/>
  </visual>
  <collision>
    <origin xyz="-0.207006 -0.452595 -0.168573" rpy="0 0 0"/>
    <geometry>
      <mesh filename="package://robot_description/meshes/right_little_pivot_1.stl" scale="0.001 0.001 0.001"/>
    </geometry>
  </collision>
</link>

<link name="left_little_pivot_1">
  <inertial>
    <origin xyz="-0.00022083740307932143 0.10298752837132685 -0.03446395454594536" rpy="0 0 0"/>
    <mass value="1.158287566383538"/>
    <inertia ixx="0.010707" iyy="0.01462" izz="0.023908" ixy="-1e-06" iyz="-0.000121" ixz="8.5e-05"/>
  </inertial>
  <visual>
    <origin xyz="-0.207006 0.452481 -0.168573" rpy="0 0 0"/>
    <geometry>
      <mesh filename="package://robot_description/meshes/left_little_pivot_1.stl" scale="0.001 0.001 0.001"/>
    </geometry>
    <material name="silver"/>
  </visual>
  <collision>
    <origin xyz="-0.207006 0.452481 -0.168573" rpy="0 0 0"/>
    <geometry>
      <mesh filename="package://robot_description/meshes/left_little_pivot_1.stl" scale="0.001 0.001 0.001"/>
    </geometry>
  </collision>
</link>

<link name="wheel_1">
  <inertial>
    <origin xyz="-2.3343628063887678e-07 -0.08910709857161447 4.492056740468264e-09" rpy="0 0 0"/>
    <mass value="11.601933377005569"/>
    <inertia ixx="0.066678" iyy="0.074767" izz="0.066678" ixy="0.0" iyz="0.0" ixz="-0.0"/>
  </inertial>
  <visual>
    <origin xyz="0.31725 -0.452595 -0.073323" rpy="0 0 0"/>
    <geometry>
      <mesh filename="package://robot_description/meshes/wheel_1.stl" scale="0.001 0.001 0.001"/>
    </geometry>
    <material name="silver"/>
  </visual>
  <collision>
    <origin xyz="0.31725 -0.452595 -0.073323" rpy="0 0 0"/>
    <geometry>
      <mesh filename="package://robot_description/meshes/wheel_1.stl" scale="0.001 0.001 0.001"/>
    </geometry>
  </collision>
</link>

<link name="wheel_2">
  <inertial>
    <origin xyz="-0.38150331945529364 -0.039295098571614784 -0.5403554023304846" rpy="0 0 0"/>
    <mass value="11.601933377005569"/>
    <inertia ixx="0.066678" iyy="0.074767" izz="0.066678" ixy="0.0" iyz="0.0" ixz="-0.0"/>
  </inertial>
  <visual>
    <origin xyz="-0.410225 -0.402783 -0.633868" rpy="0 0 0"/>
    <geometry>
      <mesh filename="package://robot_description/meshes/wheel_2.stl" scale="0.001 0.001 0.001"/>
    </geometry>
    <material name="silver"/>
  </visual>
  <collision>
    <origin xyz="-0.410225 -0.402783 -0.633868" rpy="0 0 0"/>
    <geometry>
      <mesh filename="package://robot_description/meshes/wheel_2.stl" scale="0.001 0.001 0.001"/>
    </geometry>
  </collision>
</link>

<link name="wheel_3">
  <inertial>
    <origin xyz="-0.3815036036551207 -0.04157109857161467 -0.5426314668854645" rpy="0 0 0"/>
    <mass value="11.601933377005569"/>
    <inertia ixx="0.066678" iyy="0.074767" izz="0.066678" ixy="0.0" iyz="0.0" ixz="-0.0"/>
  </inertial>
  <visual>
    <origin xyz="-0.765818 -0.405059 -0.633868" rpy="0 0 0"/>
    <geometry>
      <mesh filename="package://robot_description/meshes/wheel_3.stl" scale="0.001 0.001 0.001"/>
    </geometry>
    <material name="silver"/>
  </visual>
  <collision>
    <origin xyz="-0.765818 -0.405059 -0.633868" rpy="0 0 0"/>
    <geometry>
      <mesh filename="package://robot_description/meshes/wheel_3.stl" scale="0.001 0.001 0.001"/>
    </geometry>
  </collision>
</link>

<link name="wheel_4">
  <inertial>
    <origin xyz="-0.3591342334348961 0.11899490142838393 -0.06408999550794109" rpy="0 0 0"/>
    <mass value="11.601933377005569"/>
    <inertia ixx="0.066678" iyy="0.074767" izz="0.066678" ixy="0.0" iyz="0.0" ixz="-0.0"/>
  </inertial>
  <visual>
    <origin xyz="-0.041884 0.449636 -0.137413" rpy="0 0 0"/>
    <geometry>
      <mesh filename="package://robot_description/meshes/wheel_4.stl" scale="0.001 0.001 0.001"/>
    </geometry>
    <material name="silver"/>
  </visual>
  <collision>
    <origin xyz="-0.041884 0.449636 -0.137413" rpy="0 0 0"/>
    <geometry>
      <mesh filename="package://robot_description/meshes/wheel_4.stl" scale="0.001 0.001 0.001"/>
    </geometry>
  </collision>
</link>

<link name="wheel_5">
  <inertial>
    <origin xyz="-0.38150331945390625 -0.07190017040328195 0.36472058868693286" rpy="0 0 0"/>
    <mass value="11.601933377005569"/>
    <inertia ixx="0.066678" iyy="0.074767" izz="0.066678" ixy="-0.0" iyz="0.0" ixz="0.0"/>
  </inertial>
  <visual>
    <origin xyz="-0.410225 0.291473 0.271208" rpy="0 0 0"/>
    <geometry>
      <mesh filename="package://robot_description/meshes/wheel_5.stl" scale="0.001 0.001 0.001"/>
    </geometry>
    <material name="silver"/>
  </visual>
  <collision>
    <origin xyz="-0.410225 0.291473 0.271208" rpy="0 0 0"/>
    <geometry>
      <mesh filename="package://robot_description/meshes/wheel_5.stl" scale="0.001 0.001 0.001"/>
    </geometry>
  </collision>
</link>

<link name="wheel_6">
  <inertial>
    <origin xyz="-0.3815036036537347 -0.07417617040328273 0.3624445241319522" rpy="0 0 0"/>
    <mass value="11.601933377005569"/>
    <inertia ixx="0.066678" iyy="0.074767" izz="0.066678" ixy="-0.0" iyz="0.0" ixz="0.0"/>
  </inertial>
  <visual>
    <origin xyz="-0.765818 0.289197 0.271208" rpy="0 0 0"/>
    <geometry>
      <mesh filename="package://robot_description/meshes/wheel_6.stl" scale="0.001 0.001 0.001"/>
    </geometry>
    <material name="silver"/>
  </visual>
  <collision>
    <origin xyz="-0.765818 0.289197 0.271208" rpy="0 0 0"/>
    <geometry>
      <mesh filename="package://robot_description/meshes/wheel_6.stl" scale="0.001 0.001 0.001"/>
    </geometry>
  </collision>
</link>

<joint name="Revolute 1" type="continuous">
  <origin xyz="0.032254 -0.238359 0.327323" rpy="0 0 0"/>
  <parent link="base_link"/>
  <child link="right_big_pivot_1"/>
  <axis xyz="-0.0 -1.0 -0.0"/>
</joint>

<joint name="Revolute 3" type="continuous">
  <origin xyz="0.032254 0.2386 0.327323" rpy="0 0 0"/>
  <parent link="base_link"/>
  <child link="left_big_pivot_1"/>
  <axis xyz="0.0 1.0 0.0"/>
</joint>

<joint name="Revolute 4" type="continuous">
  <origin xyz="0.174752 0.213995 -0.15875" rpy="0 0 0"/>
  <parent link="left_big_pivot_1"/>
  <child link="right_little_pivot_1"/>
  <axis xyz="0.0 1.0 0.0"/>
</joint>

<joint name="Revolute 5" type="continuous">
  <origin xyz="0.174752 -0.214122 -0.15875" rpy="0 0 0"/>
  <parent link="right_big_pivot_1"/>
  <child link="left_little_pivot_1"/>
  <axis xyz="0.0 1.0 0.0"/>
</joint>

<joint name="Revolute 6" type="continuous">
  <origin xyz="-0.349504 0.213995 -0.254" rpy="0 0 0"/>
  <parent link="left_big_pivot_1"/>
  <child link="wheel_1"/>
  <axis xyz="-0.0 -1.0 -0.0"/>
</joint>

<joint name="Revolute 7" type="continuous">
  <origin xyz="0.203219 -0.049812 0.465295" rpy="0 0 0"/>
  <parent link="right_little_pivot_1"/>
  <child link="wheel_2"/>
  <axis xyz="-0.0 -1.0 -0.0"/>
</joint>

<joint name="Revolute 8" type="continuous">
  <origin xyz="0.558812 -0.047536 0.465295" rpy="0 0 0"/>
  <parent link="right_little_pivot_1"/>
  <child link="wheel_3"/>
  <axis xyz="0.0 1.0 0.0"/>
</joint>

<joint name="Revolute 9" type="continuous">
  <origin xyz="0.00963 -0.211277 -0.18991" rpy="0 0 0"/>
  <parent link="right_big_pivot_1"/>
  <child link="wheel_4"/>
  <axis xyz="-0.0 -1.0 -0.0"/>
</joint>

<joint name="Revolute 10" type="continuous">
  <origin xyz="0.203219 0.161008 -0.439781" rpy="0 0 0"/>
  <parent link="left_little_pivot_1"/>
  <child link="wheel_5"/>
  <axis xyz="-0.0 -1.0 -0.0"/>
</joint>

<joint name="Revolute 11" type="continuous">
  <origin xyz="0.558812 0.163284 -0.439781" rpy="0 0 0"/>
  <parent link="left_little_pivot_1"/>
  <child link="wheel_6"/>
  <axis xyz="0.0 1.0 0.0"/>
</joint>

</robot>
