<?xml version="1.0" ?>
<robot name="robot" xmlns:xacro="http://www.ros.org/wiki/xacro">

<xacro:include filename="$(find robot_description)/urdf/materials.xacro" />
<xacro:include filename="$(find robot_description)/urdf/robot.trans" />
<xacro:include filename="$(find robot_description)/urdf/robot.gazebo" />
<link name="base_link">
  <inertial>
    <origin xyz="0.03180031010101345 4.6312625487061606e-05 0.10698441033921668" rpy="0 0 0"/>
    <mass value="17.719416949374274"/>
    <inertia ixx="0.704305" iyy="1.004356" izz="1.471877" ixy="0.000745" iyz="0.000142" ixz="-0.000419"/>
  </inertial>
  <visual>
    <origin xyz="0 0 0" rpy="0 0 0"/>
    <geometry>
      <mesh filename="package://robot_description/meshes/base_link.stl" scale="0.001 0.001 0.001"/>
    </geometry>
    <material name="silver"/>
  </visual>
  <collision>
    <origin xyz="0 0 0" rpy="0 0 0"/>
    <geometry>
      <mesh filename="package://robot_description/meshes/base_link.stl" scale="0.001 0.001 0.001"/>
    </geometry>
  </collision>
</link>

<link name="right_big_pivot_1">
  <inertial>
    <origin xyz="-0.058503993766625226 -0.108547328887598 -0.07469415008342761" rpy="0 0 0"/>
    <mass value="2.2415377387384887"/>
    <inertia ixx="0.033507" iyy="0.078447" izz="0.086535" ixy="-2e-05" iyz="1e-06" ixz="-0.014743"/>
  </inertial>
  <visual>
    <origin xyz="-0.032254 0.238359 -0.15875" rpy="0 0 0"/>
    <geometry>
      <mesh filename="package://robot_description/meshes/right_big_pivot_1.stl" scale="0.001 0.001 0.001"/>
    </geometry>
    <material name="silver"/>
  </visual>
  <collision>
    <origin xyz="-0.032254 0.238359 -0.15875" rpy="0 0 0"/>
    <geometry>
      <mesh filename="package://robot_description/meshes/right_big_pivot_1.stl" scale="0.001 0.001 0.001"/>
    </geometry>
  </collision>
</link>

<link name="left_big_pivot_1">
  <inertial>
    <origin xyz="-0.05850399376799863 0.10862267111240007 -0.07469415008342495" rpy="0 0 0"/>
    <mass value="2.2415377387384736"/>
    <inertia ixx="0.033507" iyy="0.078447" izz="0.086535" ixy="-2e-05" iyz="1e-06" ixz="-0.014743"/>
  </inertial>
  <visual>
    <origin xyz="-0.032254 -0.2386 -0.15875" rpy="0 0 0"/>
    <geometry>
      <mesh filename="package://robot_description/meshes/left_big_pivot_1.stl" scale="0.001 0.001 0.001"/>
    </geometry>
    <material name="silver"/>
  </visual>
  <collision>
    <origin xyz="-0.032254 -0.2386 -0.15875" rpy="0 0 0"/>
    <geometry>
      <mesh filename="package://robot_description/meshes/left_big_pivot_1.stl" scale="0.001 0.001 0.001"/>
    </geometry>
  </collision>
</link>

<link name="right_little_pivot_1">
  <inertial>
    <origin xyz="-0.00022083740446540712 -0.10783247162867271 -0.034463954545946425" rpy="0 0 0"/>
    <mass value="1.158287566383538"/>
    <inertia ixx="0.010707" iyy="0.01462" izz="0.023908" ixy="-1e-06" iyz="-0.000121" ixz="8.5e-05"/>
  </inertial>
  <visual>
    <origin xyz="-0.207006 -0.452595 -0.0" rpy="0 0 0"/>
    <geometry>
      <mesh filename="package://robot_description/meshes/right_little_pivot_1.stl" scale="0.001 0.001 0.001"/>
    </geometry>
    <material name="silver"/>
  </visual>
  <collision>
    <origin xyz="-0.207006 -0.452595 -0.0" rpy="0 0 0"/>
    <geometry>
      <mesh filename="package://robot_description/meshes/right_little_pivot_1.stl" scale="0.001 0.001 0.001"/>
    </geometry>
  </collision>
</link>

<link name="left_little_pivot_1">
  <inertial>
    <origin xyz="-0.00022083740307884958 0.10298752837132691 -0.03446395454594424" rpy="0 0 0"/>
    <mass value="1.158287566383538"/>
    <inertia ixx="0.010707" iyy="0.01462" izz="0.023908" ixy="-1e-06" iyz="-0.000121" ixz="8.5e-05"/>
  </inertial>
  <visual>
    <origin xyz="-0.207006 0.452481 -0.0" rpy="0 0 0"/>
    <geometry>
      <mesh filename="package://robot_description/meshes/left_little_pivot_1.stl" scale="0.001 0.001 0.001"/>
    </geometry>
    <material name="silver"/>
  </visual>
  <collision>
    <origin xyz="-0.207006 0.452481 -0.0" rpy="0 0 0"/>
    <geometry>
      <mesh filename="package://robot_description/meshes/left_little_pivot_1.stl" scale="0.001 0.001 0.001"/>
    </geometry>
  </collision>
</link>

<link name="wheel_1">
  <inertial>
    <origin xyz="-2.3343628013927642e-07 -0.08910709857161442 4.492057850691289e-09" rpy="0 0 0"/>
    <mass value="11.601933377005569"/>
    <inertia ixx="0.066678" iyy="0.074767" izz="0.066678" ixy="0.0" iyz="0.0" ixz="-0.0"/>
  </inertial>
  <visual>
    <origin xyz="0.31725 -0.452595 0.09525" rpy="0 0 0"/>
    <geometry>
      <mesh filename="package://robot_description/meshes/wheel_1.stl" scale="0.001 0.001 0.001"/>
    </geometry>
    <material name="silver"/>
  </visual>
  <collision>
    <origin xyz="0.31725 -0.452595 0.09525" rpy="0 0 0"/>
    <geometry>
      <mesh filename="package://robot_description/meshes/wheel_1.stl" scale="0.001 0.001 0.001"/>
    </geometry>
  </collision>
</link>

<link name="wheel_2">
  <inertial>
    <origin xyz="-0.3815033194552931 -0.20786809857161465 -0.5403554023304835" rpy="0 0 0"/>
    <mass value="11.601933377005569"/>
    <inertia ixx="0.066678" iyy="0.074767" izz="0.066678" ixy="0.0" iyz="0.0" ixz="-0.0"/>
  </inertial>
  <visual>
    <origin xyz="-0.410225 -0.571356 -0.465295" rpy="0 0 0"/>
    <geometry>
      <mesh filename="package://robot_description/meshes/wheel_2.stl" scale="0.001 0.001 0.001"/>
    </geometry>
    <material name="silver"/>
  </visual>
  <collision>
    <origin xyz="-0.410225 -0.571356 -0.465295" rpy="0 0 0"/>
    <geometry>
      <mesh filename="package://robot_description/meshes/wheel_2.stl" scale="0.001 0.001 0.001"/>
    </geometry>
  </collision>
</link>

<link name="wheel_3">
  <inertial>
    <origin xyz="-0.38150360365512026 -0.2101440985716146 -0.5426314668854634" rpy="0 0 0"/>
    <mass value="11.601933377005569"/>
    <inertia ixx="0.066678" iyy="0.074767" izz="0.066678" ixy="0.0" iyz="0.0" ixz="-0.0"/>
  </inertial>
  <visual>
    <origin xyz="-0.765818 -0.573632 -0.465295" rpy="0 0 0"/>
    <geometry>
      <mesh filename="package://robot_description/meshes/wheel_3.stl" scale="0.001 0.001 0.001"/>
    </geometry>
    <material name="silver"/>
  </visual>
  <collision>
    <origin xyz="-0.765818 -0.573632 -0.465295" rpy="0 0 0"/>
    <geometry>
      <mesh filename="package://robot_description/meshes/wheel_3.stl" scale="0.001 0.001 0.001"/>
    </geometry>
  </collision>
</link>

<link name="wheel_4">
  <inertial>
    <origin xyz="-0.3591342334348953 -0.08218317040328155 0.14672999550947713" rpy="0 0 0"/>
    <mass value="11.601933377005569"/>
    <inertia ixx="0.066678" iyy="0.074767" izz="0.066678" ixy="-0.0" iyz="0.0" ixz="0.0"/>
  </inertial>
  <visual>
    <origin xyz="-0.041884 0.281063 0.24198" rpy="0 0 0"/>
    <geometry>
      <mesh filename="package://robot_description/meshes/wheel_4.stl" scale="0.001 0.001 0.001"/>
    </geometry>
    <material name="silver"/>
  </visual>
  <collision>
    <origin xyz="-0.041884 0.281063 0.24198" rpy="0 0 0"/>
    <geometry>
      <mesh filename="package://robot_description/meshes/wheel_4.stl" scale="0.001 0.001 0.001"/>
    </geometry>
  </collision>
</link>

<link name="wheel_5">
  <inertial>
    <origin xyz="-0.3815033194539057 -0.2404731704032818 0.36472058868693397" rpy="0 0 0"/>
    <mass value="11.601933377005569"/>
    <inertia ixx="0.066678" iyy="0.074767" izz="0.066678" ixy="-0.0" iyz="0.0" ixz="0.0"/>
  </inertial>
  <visual>
    <origin xyz="-0.410225 0.1229 0.439781" rpy="0 0 0"/>
    <geometry>
      <mesh filename="package://robot_description/meshes/wheel_5.stl" scale="0.001 0.001 0.001"/>
    </geometry>
    <material name="silver"/>
  </visual>
  <collision>
    <origin xyz="-0.410225 0.1229 0.439781" rpy="0 0 0"/>
    <geometry>
      <mesh filename="package://robot_description/meshes/wheel_5.stl" scale="0.001 0.001 0.001"/>
    </geometry>
  </collision>
</link>

<link name="wheel_6">
  <inertial>
    <origin xyz="-0.38150360365373415 -0.24274917040328264 0.3624445241319533" rpy="0 0 0"/>
    <mass value="11.601933377005569"/>
    <inertia ixx="0.066678" iyy="0.074767" izz="0.066678" ixy="-0.0" iyz="0.0" ixz="0.0"/>
  </inertial>
  <visual>
    <origin xyz="-0.765818 0.120624 0.439781" rpy="0 0 0"/>
    <geometry>
      <mesh filename="package://robot_description/meshes/wheel_6.stl" scale="0.001 0.001 0.001"/>
    </geometry>
    <material name="silver"/>
  </visual>
  <collision>
    <origin xyz="-0.765818 0.120624 0.439781" rpy="0 0 0"/>
    <geometry>
      <mesh filename="package://robot_description/meshes/wheel_6.stl" scale="0.001 0.001 0.001"/>
    </geometry>
  </collision>
</link>

<joint name="Revolute 1" type="continuous">
  <origin xyz="0.032254 -0.238359 0.15875" rpy="0 0 0"/>
  <parent link="base_link"/>
  <child link="right_big_pivot_1"/>
  <axis xyz="-0.0 -1.0 -0.0"/>
</joint>

<joint name="Revolute 3" type="continuous">
  <origin xyz="0.032254 0.2386 0.15875" rpy="0 0 0"/>
  <parent link="base_link"/>
  <child link="left_big_pivot_1"/>
  <axis xyz="0.0 1.0 0.0"/>
</joint>

<joint name="Revolute 4" type="continuous">
  <origin xyz="0.174752 0.213995 -0.15875" rpy="0 0 0"/>
  <parent link="left_big_pivot_1"/>
  <child link="right_little_pivot_1"/>
  <axis xyz="0.0 1.0 0.0"/>
</joint>

<joint name="Revolute 5" type="continuous">
  <origin xyz="0.174752 -0.214122 -0.15875" rpy="0 0 0"/>
  <parent link="right_big_pivot_1"/>
  <child link="left_little_pivot_1"/>
  <axis xyz="0.0 1.0 0.0"/>
</joint>

<joint name="Revolute 6" type="continuous">
  <origin xyz="-0.349504 0.213995 -0.254" rpy="0 0 0"/>
  <parent link="left_big_pivot_1"/>
  <child link="wheel_1"/>
  <axis xyz="-0.0 -1.0 -0.0"/>
</joint>

<joint name="Revolute 7" type="continuous">
  <origin xyz="0.203219 0.118761 0.465295" rpy="0 0 0"/>
  <parent link="right_little_pivot_1"/>
  <child link="wheel_2"/>
  <axis xyz="-0.0 -1.0 -0.0"/>
</joint>

<joint name="Revolute 8" type="continuous">
  <origin xyz="0.558812 0.121037 0.465295" rpy="0 0 0"/>
  <parent link="right_little_pivot_1"/>
  <child link="wheel_3"/>
  <axis xyz="0.0 1.0 0.0"/>
</joint>

<joint name="Revolute 9" type="continuous">
  <origin xyz="0.00963 -0.042704 -0.40073" rpy="0 0 0"/>
  <parent link="right_big_pivot_1"/>
  <child link="wheel_4"/>
  <axis xyz="-0.0 -1.0 -0.0"/>
</joint>

<joint name="Revolute 10" type="continuous">
  <origin xyz="0.203219 0.329581 -0.439781" rpy="0 0 0"/>
  <parent link="left_little_pivot_1"/>
  <child link="wheel_5"/>
  <axis xyz="-0.0 -1.0 -0.0"/>
</joint>

<joint name="Revolute 11" type="continuous">
  <origin xyz="0.558812 0.331857 -0.439781" rpy="0 0 0"/>
  <parent link="left_little_pivot_1"/>
  <child link="wheel_6"/>
  <axis xyz="0.0 1.0 0.0"/>
</joint>

</robot>
